Workbook

Sheet Test Cases
A1: ID | B1: Module | C1: Type | D1: Scenario | E1: Priority | F1: Preconditions | G1: Steps | H1: Test Data | I1: Expected Result | J1: Status | K1: Actual Result | L1: Bug | M1: Executed On
A2: TC-001 | B2: Login | C2: Functional | D2: Valid login with standard credentials | E2: High | F2: Browser open on https://www.saucedemo.com/; no user logged in | G2: 1. Enter the username in the Username field. 2. Enter the password in the Password field. 3. Click Login. | H2: Username: standard_user / Password: secret_sauce | I2: User is taken to /inventory.html. Page title is "Products"; six products, the cart icon and the menu button are displayed. | J2: Not Run
A3: TC-002 | B3: Login | C3: Negative | D3: Invalid username | E3: High | F3: Browser open on https://www.saucedemo.com/; no user logged in | G3: 1. Enter the username in the Username field. 2. Enter the password in the Password field. 3. Click Login. | H3: Username: invalid_user / Password: secret_sauce | I3: Error banner: "Epic sadface: Username and password do not match any user in this service". User stays on the login page. | J3: Not Run
A4: TC-003 | B4: Login | C4: Negative | D4: Invalid password | E4: High | F4: Browser open on https://www.saucedemo.com/; no user logged in | G4: 1. Enter the username in the Username field. 2. Enter the password in the Password field. 3. Click Login. | H4: Username: standard_user / Password: wrong_password | I4: Error banner: "Epic sadface: Username and password do not match any user in this service". User stays on the login page. | J4: Not Run
A5: TC-004 | B5: Login | C5: Negative | D5: Both fields empty | E5: High | F5: Browser open on https://www.saucedemo.com/; no user logged in | G5: 1. Leave Username empty. 2. Leave Password empty. 3. Click Login. | H5: Username: (empty) / Password: (empty) | I5: Error banner: "Epic sadface: Username is required". User stays on the login page. | J5: Not Run
A6: TC-005 | B6: Login | C6: Negative | D6: Username empty | E6: High | F6: Browser open on https://www.saucedemo.com/; no user logged in | G6: 1. Leave Username empty. 2. Enter the password. 3. Click Login. | H6: Username: (empty) / Password: secret_sauce | I6: Error banner: "Epic sadface: Username is required". | J6: Not Run
A7: TC-006 | B7: Login | C7: Negative | D7: Password empty | E7: High | F7: Browser open on https://www.saucedemo.com/; no user logged in | G7: 1. Enter the username. 2. Leave Password empty. 3. Click Login. | H7: Username: standard_user / Password: (empty) | I7: Error banner: "Epic sadface: Password is required". | J7: Not Run
A8: TC-007 | B8: Login | C8: Boundary | D8: Very long username | E8: Medium | F8: Browser open on https://www.saucedemo.com/; no user logged in | G8: 1. Enter the username in the Username field. 2. Enter the password in the Password field. 3. Click Login. | H8: Username: 256 x "a" / Password: secret_sauce | I8: Application does not crash or break the layout. Error banner: "Epic sadface: Username and password do not match any user in this service". User stays on the login page. | J8: Not Run
A9: TC-008 | B9: Login | C9: Boundary | D9: Very long password | E9: Medium | F9: Browser open on https://www.saucedemo.com/; no user logged in | G9: 1. Enter the username in the Username field. 2. Enter the password in the Password field. 3. Click Login. | H9: Username: standard_user / Password: 256 x "a" | I9: Application does not crash or break the layout. Error banner: "Epic sadface: Username and password do not match any user in this service". User stays on the login page. | J9: Not Run
A10: TC-009 | B10: Login | C10: Negative | D10: Username with leading/trailing spaces | E10: Medium | F10: Browser open on https://www.saucedemo.com/; no user logged in | G10: 1. Enter the username in the Username field. 2. Enter the password in the Password field. 3. Click Login. | H10: Username: " standard_user " (one leading and one trailing space) / Password: secret_sauce | I10: Either the whitespace is trimmed and login succeeds, or a clear credentials error is shown. No unhandled error. Record the exact behaviour; BUG-01 is raised against this case in the index. | J10: Not Run | L10: BUG-01
A11: TC-010 | B11: Login | C11: Functional | D11: Password masking | E11: Medium | F11: Browser open on https://www.saucedemo.com/; no user logged in | G11: 1. Type a password into the Password field. 2. Look at the field while typing and after. | H11: Password: secret_sauce | I11: Characters are masked (dots/bullets). The password is not shown in clear text. | J11: Not Run
A12: TC-011 | B12: Login | C12: Negative | D12: Locked account | E12: High | F12: Browser open on https://www.saucedemo.com/; no user logged in | G12: 1. Enter the username in the Username field. 2. Enter the password in the Password field. 3. Click Login. | H12: Username: locked_out_user / Password: secret_sauce | I12: Error banner: "Epic sadface: Sorry, this user has been locked out." User is not logged in and stays on the login page. | J12: Not Run
A13: TC-012 | B13: Login | C13: Negative | D13: Case-sensitive username | E13: Medium | F13: Browser open on https://www.saucedemo.com/; no user logged in | G13: 1. Enter the username in the Username field. 2. Enter the password in the Password field. 3. Click Login. | H13: Username: Standard_User (different capitalisation) / Password: secret_sauce | I13: Error banner: "Epic sadface: Username and password do not match any user in this service". User stays on the login page. | J13: Not Run
A14: TC-013 | B14: Inventory | C14: Functional | D14: Six products displayed | E14: High | F14: Logged in as standard_user; Products page displayed; cart empty | G14: 1. Look at the product list on the Products page. | H14: n/a | I14: Exactly six products are listed: Sauce Labs Backpack, Bike Light, Bolt T-Shirt, Fleece Jacket, Onesie and Test.allTheThings() T-Shirt (Red). | J14: Not Run
A15: TC-014 | B15: Inventory | C15: Functional | D15: Product name/price/image/description present | E15: High | F15: Logged in as standard_user; Products page displayed; cart empty | G15: 1. For each of the six products, check what is displayed on its card. | H15: n/a | I15: Every card shows a product image (loaded, not broken), name, description, price and an Add to cart button. | J15: Not Run
A16: TC-015 | B16: Inventory | C16: Functional | D16: Add first product to cart | E16: High | F16: Logged in as standard_user; Products page displayed; cart empty | G16: 1. Click Add to cart on the first product (Sauce Labs Backpack). | H16: Product: Sauce Labs Backpack | I16: Button changes to "Remove". Cart badge shows 1. | J16: Not Run
A17: TC-016 | B17: Inventory | C17: Functional | D17: Remove product from inventory page | E17: High | F17: Logged in as standard_user; Backpack already added from the Products page (badge = 1) | G17: 1. Click Remove on the Backpack card. | H17: Product: Sauce Labs Backpack | I17: Button reverts to "Add to cart". Cart badge disappears. | J17: Not Run
A18: TC-017 | B18: Inventory | C18: Functional | D18: Cart badge count for multiple products | E18: High | F18: Logged in as standard_user; Products page displayed; cart empty | G18: 1. Click Add to cart on three different products, one at a time. 2. Check the cart badge after each click. | H18: Products: Backpack, Bike Light, Bolt T-Shirt | I18: Badge shows 1, then 2, then 3. Each clicked button changes to "Remove". | J18: Not Run
A19: TC-018 | B19: Inventory | C19: Functional | D19: Sort A-Z | E19: Medium | F19: Logged in as standard_user; Products page displayed; cart empty | G19: 1. Open the sort dropdown. 2. Select "Name (A to Z)". | H19: Sort: Name (A to Z) | I19: Order: Sauce Labs Backpack, Sauce Labs Bike Light, Sauce Labs Bolt T-Shirt, Sauce Labs Fleece Jacket, Sauce Labs Onesie, Test.allTheThings() T-Shirt (Red). | J19: Not Run
A20: TC-019 | B20: Inventory | C20: Functional | D20: Sort Z-A | E20: Medium | F20: Logged in as standard_user; Products page displayed; cart empty | G20: 1. Open the sort dropdown. 2. Select "Name (Z to A)". | H20: Sort: Name (Z to A) | I20: Exact reverse of A to Z: Test.allTheThings() T-Shirt (Red) first, Sauce Labs Backpack last. | J20: Not Run
A21: TC-020 | B21: Inventory | C21: Boundary | D21: Sort Price Low-High | E21: Medium | F21: Logged in as standard_user; Products page displayed; cart empty | G21: 1. Open the sort dropdown. 2. Select "Price (low to high)". | H21: Sort: Price (low to high) | I21: Prices ascend: $7.99, $9.99, $15.99, $15.99, $29.99, $49.99 (Onesie, Bike Light, the two $15.99 T-shirts, Backpack, Fleece Jacket). Index lists BUG-10 against this case; confirm the reference on execution (BUG-10 otherwise relates to error_user checkout). | J21: Not Run | L21: BUG-10
A22: TC-021 | B22: Inventory | C22: Boundary | D22: Sort Price High-Low | E22: Medium | F22: Logged in as standard_user; Products page displayed; cart empty | G22: 1. Open the sort dropdown. 2. Select "Price (high to low)". | H22: Sort: Price (high to low) | I22: Prices descend: $49.99, $29.99, $15.99, $15.99, $9.99, $7.99. | J22: Not Run
A23: TC-022 | B23: Inventory | C23: Functional | D23: Open product from name | E23: High | F23: Logged in as standard_user; Products page displayed; cart empty | G23: 1. Click the product name "Sauce Labs Backpack". | H23: Product: Sauce Labs Backpack | I23: Product detail page opens (/inventory-item.html?id=4) showing the Backpack. | J23: Not Run
A24: TC-023 | B24: Inventory | C24: Functional | D24: Open product from image | E24: High | F24: Logged in as standard_user; Products page displayed; cart empty | G24: 1. Click the product image of "Sauce Labs Backpack". | H24: Product: Sauce Labs Backpack | I24: Same product detail page as TC-022 opens, for the Backpack. | J24: Not Run
A25: TC-024 | B25: Inventory | C25: Functional | D25: Reset App State | E25: Medium | F25: Logged in as standard_user; two products added to cart (badge = 2) | G25: 1. Click the menu (burger) button. 2. Click "Reset App State". 3. Close the menu. | H25: n/a | I25: Cart is emptied and the badge disappears. Product buttons show "Add to cart" (note whether a page refresh is needed for button states to reset). | J25: Not Run
A26: TC-025 | B26: Product Detail | C26: Functional | D26: Correct product detail data | E26: High | F26: Logged in as standard_user; Products page displayed; cart empty | G26: 1. Open each product from the list. 2. Compare name, description, price and image with the Products page. | H26: All six products | I26: Each detail page shows the same name, description, price and image as the product card that was clicked. | J26: Not Run
A27: TC-026 | B27: Product Detail | C27: Functional | D27: Back to Products | E27: Medium | F27: Logged in as standard_user; a product detail page is open | G27: 1. Click "Back to products". | H27: n/a | I27: User returns to the Products page (/inventory.html). | J27: Not Run
A28: TC-027 | B28: Product Detail | C28: Functional | D28: Add to cart from detail | E28: High | F28: Logged in as standard_user; Backpack detail page open; cart empty | G28: 1. Click "Add to cart". | H28: Product: Sauce Labs Backpack | I28: Button changes to "Remove". Cart badge shows 1. | J28: Not Run
A29: TC-028 | B29: Product Detail | C29: Functional | D29: Remove from cart from detail | E29: High | F29: Logged in as standard_user; Backpack detail page open; Backpack in cart | G29: 1. Click "Remove". | H29: Product: Sauce Labs Backpack | I29: Button reverts to "Add to cart". Cart badge disappears. | J29: Not Run
A30: TC-029 | B30: Product Detail | C30: Negative | D30: Problem user wrong detail mapping | E30: High | F30: Logged in as problem_user; Products page displayed; cart empty | G30: 1. Click a product name, e.g. "Sauce Labs Backpack". 2. Compare the detail page with the product that was clicked. 3. Repeat for the other products. | H30: Account: problem_user / secret_sauce | I30: The detail page shows the product that was clicked (same name, price, description and image). | J30: Not Run | L30: BUG-06
A31: TC-030 | B31: Product Detail | C31: Negative | D31: Problem user detail Add to Cart | E31: High | F31: Logged in as problem_user; Products page displayed; cart empty; a product detail page is open | G31: 1. Click "Add to cart" on the detail page. 2. Check the button and the cart badge. | H31: Account: problem_user / secret_sauce | I31: Button changes to "Remove" and the badge increases by 1 for that product. | J31: Not Run | L31: BUG-05
A32: TC-031 | B32: Product Detail | C32: Negative | D32: Error user description visibility | E32: Medium | F32: Logged in as error_user; Products page displayed; cart empty | G32: 1. Open a product detail page. 2. Compare the description with the one on the Products page. | H32: Account: error_user / secret_sauce | I32: The product description is visible and matches the Products page. | J32: Not Run | L32: BUG-08
A33: TC-032 | B33: Cart | C33: Functional | D33: Open cart | E33: High | F33: Logged in as standard_user; Products page displayed; cart empty | G33: 1. Click the cart icon. | H33: n/a | I33: Cart page opens (/cart.html) with title "Your Cart", QTY and Description headers, Continue Shopping and Checkout buttons. | J33: Not Run
A34: TC-033 | B34: Cart | C34: Functional | D34: Added item appears | E34: High | F34: Logged in as standard_user; Backpack added to cart | G34: 1. Click the cart icon. 2. Check the listed item. | H34: Product: Sauce Labs Backpack | I34: Backpack is listed with QTY 1, its description and price $29.99. | J34: Not Run
A35: TC-034 | B35: Cart | C35: Functional | D35: Remove item | E35: High | F35: Logged in as standard_user; Sauce Labs Backpack added to cart; Your Cart page open | G35: 1. Click Remove next to the Backpack. | H35: Product: Sauce Labs Backpack | I35: Item disappears from the cart. Cart badge disappears. | J35: Not Run
A36: TC-035 | B36: Cart | C36: Functional | D36: Continue shopping | E36: Medium | F36: Logged in as standard_user; Sauce Labs Backpack added to cart; Your Cart page open | G36: 1. Click "Continue Shopping". | H36: n/a | I36: User returns to the Products page; the Backpack still shows "Remove" and the badge still shows 1. | J36: Not Run
A37: TC-036 | B37: Cart | C37: Functional | D37: Checkout from cart | E37: High | F37: Logged in as standard_user; Sauce Labs Backpack added to cart; Your Cart page open | G37: 1. Click "Checkout". | H37: n/a | I37: Checkout: Your Information page opens (/checkout-step-one.html). | J37: Not Run
A38: TC-037 | B38: Cart | C38: Boundary | D38: Empty cart display | E38: Medium | F38: Logged in as standard_user; Products page displayed; cart empty | G38: 1. Click the cart icon with nothing added. 2. Observe the page. | H38: n/a | I38: Cart page shows no items and no badge. Continue Shopping and Checkout buttons are visible. Also record whether Checkout can be clicked with an empty cart and what happens. | J38: Not Run
A39: TC-038 | B39: Cart | C39: Negative | D39: Problem user remove item | E39: High | F39: Logged in as problem_user; Products page displayed; cart empty | G39: 1. Add a product to the cart. 2. Open the cart. 3. Click Remove on the item. | H39: Account: problem_user / secret_sauce | I39: Item is removed from the cart and the badge disappears. | J39: Not Run
A40: TC-039 | B40: Cart | C40: Negative | D40: Error user add/remove affected item | E40: High | F40: Logged in as error_user; Products page displayed; cart empty | G40: 1. Click Add to cart on each of the six products, one by one, checking the badge. 2. Click Remove on each, checking the badge. | H40: Account: error_user / secret_sauce | I40: Every product can be added and removed; the badge and button state update correctly each time. | J40: Not Run | L40: BUG-09
...

Sheet Summary
A1: SauceDemo manual test execution summary
A2: Counts are formulas over the Test Cases sheet. Update the Status column there; this sheet recalculates.
A4: Status | B4: Cases
A5: Not Run | B5: =COUNTIF('Test Cases'!$J$2:$J$56,A5) -> 55
A6: Pass | B6: =COUNTIF('Test Cases'!$J$2:$J$56,A6) -> 0
A7: Fail | B7: =COUNTIF('Test Cases'!$J$2:$J$56,A7) -> 0
A8: Blocked | B8: =COUNTIF('Test Cases'!$J$2:$J$56,A8) -> 0
A9: Skipped | B9: =COUNTIF('Test Cases'!$J$2:$J$56,A9) -> 0
A10: Total | B10: =COUNTA('Test Cases'!$A$2:$A$56) -> 55
A11: Check (statuses sum to total) | B11: =IF(SUM(B5:B9)=B10,"OK","MISMATCH") -> OK
A13: Module | B13: Not Run | C13: Pass | D13: Fail | E13: Blocked | F13: Total
A14: Login | B14: =COUNTIFS('Test Cases'!$B$2:$B$56,$A14,'Test Cases'!$J$2:$J$56,B$13) -> 12 | C14: =COUNTIFS('Test Cases'!$B$2:$B$56,$A14,'Test Cases'!$J$2:$J$56,C$13) -> 0 | D14: =COUNTIFS('Test Cases'!$B$2:$B$56,$A14,'Test Cases'!$J$2:$J$56,D$13) -> 0 | E14: =COUNTIFS('Test Cases'!$B$2:$B$56,$A14,'Test Cases'!$J$2:$J$56,E$13) -> 0 | F14: =COUNTIF('Test Cases'!$B$2:$B$56,$A14) -> 12
A15: Inventory | B15: =COUNTIFS('Test Cases'!$B$2:$B$56,$A15,'Test Cases'!$J$2:$J$56,B$13) -> 12 | C15: =COUNTIFS('Test Cases'!$B$2:$B$56,$A15,'Test Cases'!$J$2:$J$56,C$13) -> 0 | D15: =COUNTIFS('Test Cases'!$B$2:$B$56,$A15,'Test Cases'!$J$2:$J$56,D$13) -> 0 | E15: =COUNTIFS('Test Cases'!$B$2:$B$56,$A15,'Test Cases'!$J$2:$J$56,E$13) -> 0 | F15: =COUNTIF('Test Cases'!$B$2:$B$56,$A15) -> 12
A16: Product Detail | B16: =COUNTIFS('Test Cases'!$B$2:$B$56,$A16,'Test Cases'!$J$2:$J$56,B$13) -> 7 | C16: =COUNTIFS('Test Cases'!$B$2:$B$56,$A16,'Test Cases'!$J$2:$J$56,C$13) -> 0 | D16: =COUNTIFS('Test Cases'!$B$2:$B$56,$A16,'Test Cases'!$J$2:$J$56,D$13) -> 0 | E16: =COUNTIFS('Test Cases'!$B$2:$B$56,$A16,'Test Cases'!$J$2:$J$56,E$13) -> 0 | F16: =COUNTIF('Test Cases'!$B$2:$B$56,$A16) -> 7
A17: Cart | B17: =COUNTIFS('Test Cases'!$B$2:$B$56,$A17,'Test Cases'!$J$2:$J$56,B$13) -> 8 | C17: =COUNTIFS('Test Cases'!$B$2:$B$56,$A17,'Test Cases'!$J$2:$J$56,C$13) -> 0 | D17: =COUNTIFS('Test Cases'!$B$2:$B$56,$A17,'Test Cases'!$J$2:$J$56,D$13) -> 0 | E17: =COUNTIFS('Test Cases'!$B$2:$B$56,$A17,'Test Cases'!$J$2:$J$56,E$13) -> 0 | F17: =COUNTIF('Test Cases'!$B$2:$B$56,$A17) -> 8
A18: Checkout | B18: =COUNTIFS('Test Cases'!$B$2:$B$56,$A18,'Test Cases'!$J$2:$J$56,B$13) -> 11 | C18: =COUNTIFS('Test Cases'!$B$2:$B$56,$A18,'Test Cases'!$J$2:$J$56,C$13) -> 0 | D18: =COUNTIFS('Test Cases'!$B$2:$B$56,$A18,'Test Cases'!$J$2:$J$56,D$13) -> 0 | E18: =COUNTIFS('Test Cases'!$B$2:$B$56,$A18,'Test Cases'!$J$2:$J$56,E$13) -> 0 | F18: =COUNTIF('Test Cases'!$B$2:$B$56,$A18) -> 11
A19: Order Overview | B19: =COUNTIFS('Test Cases'!$B$2:$B$56,$A19,'Test Cases'!$J$2:$J$56,B$13) -> 5 | C19: =COUNTIFS('Test Cases'!$B$2:$B$56,$A19,'Test Cases'!$J$2:$J$56,C$13) -> 0 | D19: =COUNTIFS('Test Cases'!$B$2:$B$56,$A19,'Test Cases'!$J$2:$J$56,D$13) -> 0 | E19: =COUNTIFS('Test Cases'!$B$2:$B$56,$A19,'Test Cases'!$J$2:$J$56,E$13) -> 0 | F19: =COUNTIF('Test Cases'!$B$2:$B$56,$A19) -> 5
A21: Priority | B21: Cases
A22: Critical | B22: =COUNTIF('Test Cases'!$E$2:$E$56,A22) -> 4
A23: High | B23: =COUNTIF('Test Cases'!$E$2:$E$56,A23) -> 33
A24: Medium | B24: =COUNTIF('Test Cases'!$E$2:$E$56,A24) -> 18
A25: Low | B25: =COUNTIF('Test Cases'!$E$2:$E$56,A25) -> 0

Sheet Test Data
A1: Demo user | B1: Password | C1: Behaviour
A2: standard_user | B2: secret_sauce | C2: Baseline account; expected to behave correctly.
A3: locked_out_user | B3: secret_sauce | C3: Login is blocked with a locked-out message.
A4: problem_user | B4: secret_sauce | C4: Account used to look for UI and flow problems (TC-029, 030, 038, 049).
A5: performance_glitch_user | B5: secret_sauce | C5: Slower responses; allow extra time when logging in.
A6: error_user | B6: secret_sauce | C6: Account used to look for action errors (TC-031, 039, 050, 055).
A7: visual_user | B7: secret_sauce | C7: Account used to look for visual differences.
A9: Product | B9: Price | C9: Notes
A10: Sauce Labs Backpack | B10: 29.99 | C10: Product id 4
A11: Sauce Labs Bike Light | B11: 9.99
A12: Sauce Labs Bolt T-Shirt | B12: 15.99
A13: Sauce Labs Fleece Jacket | B13: 49.99
A14: Sauce Labs Onesie | B14: 7.99
A15: Test.allTheThings() T-Shirt (Red) | B15: 15.99
A17: Message | C17: Exact text
A18: Wrong credentials | C18: Epic sadface: Username and password do not match any user in this service
A19: Username missing | C19: Epic sadface: Username is required
A20: Password missing | C20: Epic sadface: Password is required
A21: Locked out | C21: Epic sadface: Sorry, this user has been locked out.
A22: First name missing | C22: Error: First Name is required
A23: Last name missing | C23: Error: Last Name is required
A24: Postal code missing | C24: Error: Postal Code is required
A25: Order complete | C25: Thank you for your order!
A27: Tax rate | B27: 0.08 | C27: Expected 8% sales tax on the item total; confirm on execution (TC-052).
A28: Source | C28: Public demo credentials and product catalogue published on the SauceDemo login page.
